# Bug Report: SQLite3 Object Missing temp_path Attribute

## Issue Description
When running the database_operations.py example, it fails with an AttributeError indicating that the SQLite3 object doesn't have a 'temp_path' attribute.

## Error Details
```
AttributeError: 'SQLite3' object has no attribute 'temp_path'
File: /data/gpfs/projects/punim2354/ywatanabe/.claude-worktree/mngs_repo/src/mngs/db/_SQLite3Mixins/_ConnectionMixin.py
Line: 88
```

## Steps to Reproduce
1. Run the database operations example:
   ```bash
   cd examples/mngs/db
   python database_operations.py
   ```
2. The script starts successfully and creates output directory
3. Fails when trying to close the database connection

## Expected Behavior
The SQLite3 database connection should close cleanly without errors.

## Actual Behavior
The close() method in _ConnectionMixin.py tries to access self.temp_path which doesn't exist on the SQLite3 object.

## Root Cause Analysis
Looking at the error trace:
```python
# In _ConnectionMixin.py line 88:
if self.temp_path and os.path.exists(self.temp_path):
```

The SQLite3 class or its mixins don't properly initialize the temp_path attribute, but the close() method expects it to exist.

## Proposed Fix
1. **Option 1**: Initialize temp_path in SQLite3.__init__() method:
   ```python
   self.temp_path = None  # or appropriate default
   ```

2. **Option 2**: Use hasattr() check in close() method:
   ```python
   if hasattr(self, 'temp_path') and self.temp_path and os.path.exists(self.temp_path):
   ```

3. **Option 3**: Use getattr() with default:
   ```python
   if getattr(self, 'temp_path', None) and os.path.exists(self.temp_path):
   ```

## Impact
- Affects all SQLite3 database operations that call close()
- Prevents proper cleanup of database connections
- Makes database examples fail

## Priority
**HIGH** - This breaks basic database functionality and prevents examples from running successfully.

## Progress
- [x] Investigate SQLite3 class initialization
- [x] Check where temp_path should be set
- [x] Implement fix
- [x] Test database operations example
- [x] Verify all database functionality works

## Resolution
Fixed by initializing `self.temp_path = None` in `_ConnectionMixin.__init__()` and adding a safer check in the `close()` method using `hasattr()`. The database operations example now runs without the AttributeError.

**Status**: RESOLVED
**Fixed in**: `/src/mngs/db/_SQLite3Mixins/_ConnectionMixin.py`
**Date**: 2025-05-31